Workbook

Sheet Petunjuk
A1: Data Laptop: Lima Laptop Awal (Draf 2)
A3: Tujuan
B4: Satu bentuk data yang sama untuk semua laptop, sebelum situsnya dibuat. Lima laptop awal sudah diisi dari situs pabrikan, Intel, AMD, Microsoft, ulasan teknologi, dan marketplace besar (dicek 8 Oktober 2026). Isian ini masih draf: periksa ulang, lalu lengkapi bagian yang kosong atau bertanda unknown.
A6: Cara memakai
A7: 1 | B7: Tab Model: data yang sama untuk semua konfigurasi satu seri (bahan bodi, ukuran layar, port, catatan).
A8: 2 | B8: Tab Varian: satu baris untuk satu konfigurasi nyata (CPU, RAM, dan penyimpanan tertentu). Layar, bobot, baterai, dan kelengkapan lain ada di sini karena bisa berbeda tiap varian.
A9: 3 | B9: Tab CPU dan GPU: satu baris untuk setiap prosesor dan kartu grafis. Tab Varian memilih dari dua tab ini, jadi isi keduanya lebih dulu bila menambah laptop baru. Tingkat 1-5 adalah usulan awal untuk ditinjau. Arti tiap tingkat ada di tab Aturan (bagian 6).
A10: 4 | B10: Tab Harga: harga bertanggal beserta sumbernya. Tambahkan baris baru setiap kali harga dicek ulang; jangan menimpa harga lama.
A11: 5 | B11: Tab Catatan Pengisian: sumber, kolom yang sulit dicari, kolom yang masih unknown, dan temuan untuk tiap laptop. Catat juga berapa menit kamu memeriksa tiap laptop.
A13: Arti warna
A14: Kuning | B14: Diisi sendiri. Sel kuning yang masih kosong berarti belum ada sumbernya.
A15: Abu-abu | B15: Terisi otomatis dari rumus. Jangan diketik.
A16: CONTOH | B16: Baris ke-4 di setiap tab berisi nilai rekaan untuk menunjukkan cara mengisi. Jangan dihapus dan jangan dipakai sebagai data.
A18: Aturan isi
A19: 1 | B19: Urutan sumber: spesifikasi resmi pabrikan, lalu manual servis resmi, lalu video bongkar. Informasi dari forum atau ulasan ditandai belum terverifikasi.
A20: 2 | B20: Kalau belum tahu, pilih unknown atau biarkan kosong. Jangan menebak, terutama untuk RAM disolder dan penyimpanan yang bisa diganti.
A21: 3 | B21: Harga ditulis sebagai rentang, lengkap dengan sumber dan tanggal cek. Listing yang jauh di atas atau di bawah harga toko lain tidak dihitung; alasannya ditulis di kolom catatan.
A22: 4 | B22: Tingkat 1-5 untuk CPU dan GPU adalah penilaian kita sendiri. Tulis alasannya di kolom sebelahnya.
A23: 5 | B23: Catatan editor memakai bahasa awam (lihat panduan gaya bahasa awam di dokumen Fondasi Proyek).
A24: 6 | B24: Jangan menyalin kalimat dari situs lain. Tulis ulang dengan kalimat sendiri.
A25: 7 | B25: Jangan mengubah isi daftar di tab Pilihan tanpa kesepakatan, karena tab lain memakainya.
A27: Wajib untuk v1
B28: Kode varian, tahun rilis, status penjualan, CPU, GPU, RAM (ukuran, tipe, letak), penyimpanan (ukuran, tipe, bisa diganti atau tidak), sistem operasi, harga, dan catatan editor.
A30: Tab penilaian
A31: 1 | B31: Aturan: batas minimal dan batas nyaman untuk lima kebutuhan, peringkat jenis layar, daftar peringatan, dan arti tingkat 1-5. Kolom kuning boleh diubah; tab Perhitungan dan Hasil ikut berubah.
A32: 2 | B32: Perhitungan: satu baris untuk satu pasangan varian dan kebutuhan. Semuanya rumus, jadi tidak diisi. Dipakai untuk menelusuri bagaimana hasil didapat.
A33: 3 | B33: Hasil: pilih satu varian untuk membaca alasan tiap kebutuhan, atau lihat semua varian sekaligus di tabel bawahnya.
A34: 4 | B34: Hasil ini baru percobaan aturan pada lima laptop. Angka batas dan tingkat 1-5 adalah penilaian awal kita, belum diuji ke pengguna. Isi tab Varian dengan benar dan lengkap dulu, karena kolom yang kosong atau unknown membuat hasilnya Data belum lengkap.

Sheet Model
A1: Model: satu baris untuk satu seri laptop
A2: Data yang sama untuk semua konfigurasi seri ini. Kolom kuning diisi sendiri; baris CONTOH hanya untuk ditiru.
A3: Kunci model kunci_model | B3: Merek merek | C3: Seri / nama model seri | D3: Peran dalam 5 laptop awal peran | E3: Tahun rilis seri tahun_rilis | F3: Status penjualan status | G3: Bahan bodi bahan | H3: Layar · ukuran (inci) layar_inci | I3: USB-A · jumlah port usb_a | J3: USB-C · jumlah port usb_c | K3: USB-C · kemampuan usbc_jenis | L3: Bisa diisi lewat USB-C? usbc_charge | M3: Port HDMI? hdmi | N3: HDMI · versi hdmi_versi | O3: Pembaca kartu SD? sd | P3: Port LAN (kabel)? lan | Q3: Ringkasnya (1-2 kalimat, bahasa awam) ringkasan | R3: Waspadai waspada | S3: Masalah umum yang sering dikeluhkan masalah_umum | T3: Tautan spesifikasi resmi url_spek | U3: Tanggal diperiksa tgl_verif
A4: contoh-a14 | B4: Contoh | C4: A14 | D4: Baru populer | E4: 2023 | F4: dijual | G4: Plastik | H4: 14 | I4: 2 | J4: 1 | K4: USB-C + DisplayPort | L4: ya | M4: ya | N4: HDMI 1.4 | O4: ya | P4: tidak | Q4: (CONTOH) Laptop tipis untuk kuliah dan kerja kantoran. | R4: (CONTOH) RAM disolder, tidak bisa ditambah. | S4: (CONTOH) Belum ada keluhan yang sering muncul. | T4: https://contoh.example/a14 | U4: 46303
A5: asus-m1405ya | B5: ASUS | C5: Vivobook 14 M1405YA | D5: Baru populer | E5: 2023 | F5: dijual | G5: unknown | H5: 14 | I5: 3 | J5: 1 | K5: unknown | L5: unknown | M5: ya | N5: HDMI 1.4 | O5: tidak | P5: tidak | Q5: Laptop 14 inci untuk kuliah dan pekerjaan harian. Layarnya berbentuk 16:10, sedikit lebih tinggi daripada layar laptop biasa, sehingga lebih lega untuk dokumen dan halaman web. | R5: Sebagian RAM (8 GB) menempel di papan utama dan tidak bisa diganti. Ada satu slot untuk RAM tambahan, dengan batas total 16 GB. Slot SSD hanya cocok untuk SSD satu sisi. Tidak ada pembaca kartu SD. | T5: https://asus.com/laptops/for-home/vivobook/asus-vivobook-14-oled-m1405/techspec | U5: 46303
A6: hp-pavilion-x360-14 | B6: HP | C6: Pavilion x360 14-ek1000 | D6: Baru tipis atau 2-in-1 | E6: 2023 | F6: unknown | G6: unknown | H6: 14 | I6: 2 | J6: 1 | K6: USB-C + DisplayPort | L6: unknown | M6: ya | N6: HDMI 2.1 | O6: ya | P6: tidak | Q6: Laptop 2-in-1 14 inci. Layarnya sentuh dan engselnya bisa dilipat penuh sampai seperti tablet. Bobotnya sekitar 1,5 kg. | R6: RAM 16 GB menempel di papan utama, jadi tidak bisa ditambah. Pembaca kartunya hanya untuk microSD, bukan kartu SD biasa. | T6: https://hp.com/id-id/shop/hp-pavilion-x360-2-in-1-laptop-14-ek1005tu-7n725pa.html | U6: 46303
A7: axioo-hype-10 | B7: Axioo | C7: Hype 10 | D7: Merek lokal | F7: unknown | G7: unknown | H7: 14.1 | I7: 3 | J7: 2 | K7: USB-C data saja | L7: tidak | M7: ya | N7: unknown | O7: tidak | P7: tidak | Q7: Laptop 14 inci kelas harga terjangkau dengan prosesor Celeron, untuk tugas ringan seperti mengetik, internet, dan menonton video. Di situs Axioo, laptop ini tertulis sebagai Hype 1 Intel. | R7: Layarnya HD 1366x768 jenis TN, jadi kurang tajam dan sudut pandangnya sempit. RAM memakai satu slot dengan batas 8 GB, jadi tidak bisa ditambah dari 8 GB. Kedua port USB-C hanya untuk data. Sebagian unit di toko masih memakai Windows 10, yang dukungan resminya berakhir pada 14 Oktober 2025. | T7: https://axiooworld.com/product/compare/hype-1-intel/pongo-735 | U7: 46303
A8: lenovo-thinkpad-t480 | B8: Lenovo | C8: ThinkPad T480 | D8: Bekas 1 | E8: 2018 | F8: bekas_saja | G8: Campuran | H8: 14 | I8: 2 | J8: 2 | K8: Thunderbolt 3 | L8: ya | M8: ya | N8: HDMI 1.4 | O8: ya | P8: ya | Q8: Laptop bisnis 14 inci rilisan 2018 yang mudah dibongkar: RAM dan penyimpanan bisa diganti sendiri, dan baterai luarnya bisa diganti saat laptop menyala. | R8: Hanya beredar bekas, jadi kondisi baterai, layar, dan keyboard tiap unit berbeda. Menurut Lenovo, penyimpanan utama memakai satu slot hard disk 2,5 inci atau satu slot M.2 2280, bukan keduanya sekaligus. Pilihan layar dan baterainya beragam, jadi cek konfigurasi unit sebelum membeli. | T8: https://psref.lenovo.com/syspool/Sys/PDF/ThinkPad/ThinkPad_T480/ThinkPad_T480_Spec.PDF | U8: 46303
A9: dell-latitude-5400 | B9: Dell | C9: Latitude 5400 | D9: Bekas 2 | E9: 2019 | F9: bekas_saja | G9: Serat karbon (komposit) | H9: 14 | I9: 3 | J9: 1 | K9: USB-C + DisplayPort | L9: unknown | M9: ya | N9: HDMI 1.4 | O9: ya | P9: ya | Q9: Laptop bisnis 14 inci rilisan 2019 dengan bodi serat karbon dan port lengkap: HDMI, kabel LAN, USB-C, dan microSD. Dua slot RAM bisa diisi sampai 32 GB. | R9: Hanya beredar bekas, jadi cek kondisi baterai dan layar tiap unit. Pada unit dengan baterai 4-sel, ruang hard disk 2,5 inci tidak bisa dipakai (catatan manual servis Dell). Pembaca kartunya hanya microSD. Kemampuan Thunderbolt pada port USB-C bersifat opsional menurut Dell. | T9: https://www.dell.com/support/product-details/en-us/product/latitude-14-5400-laptop/resources/manuals | U9: 46303

Sheet Varian
A1: Varian: satu baris untuk satu konfigurasi nyata
A2: Satu model bisa punya banyak varian (CPU, RAM, penyimpanan, layar berbeda). Pilih model, CPU, dan GPU dari daftar. Kolom abu-abu terisi otomatis.
A3: ID varian id_varian | B3: Model kunci_model | C3: Kode varian lengkap kode_varian | D3: Tahun rilis varian tahun_rilis | E3: Status penjualan status_penjualan | F3: Tahun dihentikan tahun_dihentikan | G3: Pasar pasar | H3: Segmen menurut pabrikan segmen_resmi | I3: Target pengguna menurut pabrikan target_resmi | J3: CPU cpu | K3: GPU gpu | L3: GPU · daya (watt) gpu_tgp | M3: RAM · ukuran (GB) ram_gb | N3: RAM · tipe ram_tipe | O3: RAM · kecepatan (MT/s) ram_mts | P3: RAM · channel ram_channel | Q3: RAM · letak (disolder / slot) ram_layout | R3: RAM · jumlah slot ram_slot_total | S3: RAM · slot kosong ram_slot_kosong | T3: RAM · bagian disolder (GB) ram_disolder_gb | U3: RAM · maksimal (GB) ram_maks_gb | V3: Penyimpanan · ukuran (GB) st_gb | W3: Penyimpanan · tipe st_tipe | X3: Penyimpanan · antarmuka st_antarmuka | Y3: Penyimpanan · bentuk st_form | Z3: Penyimpanan · bisa diganti? st_bisa_diganti | AA3: Slot M.2 · total st_m2_total | AB3: Slot M.2 · kosong st_m2_kosong | AC3: Ruang 2,5 inci kosong? st_25_kosong | AD3: Verifikasi info upgrade verif_upgrade | AE3: Sumber info upgrade sumber_upgrade | AF3: Bobot (kg) bobot_kg | AG3: Layar · jenis panel panel | AH3: Layar · resolusi resolusi | AI3: Layar · refresh rate (Hz) refresh_hz | AJ3: Layar sentuh? sentuh | AK3: Baterai (Wh) baterai_wh | AL3: Charger (watt) charger_w | AM3: Wi-Fi wifi | AN3: Bluetooth (versi) bluetooth | AO3: Sensor sidik jari? sidik_jari | AP3: Keyboard berlampu? kb_lampu | AQ3: Webcam webcam | AR3: Sistem operasi bawaan os | AS3: Edisi OS os_edisi | AT3: Office bawaan office | AU3: Garansi · jenis garansi_jenis | AV3: Garansi · lama (bulan) garansi_bulan | AW3: Garansi · baterai (bulan) garansi_baterai | AX3: Tersedia baru? tersedia_baru | AY3: Tersedia bekas? tersedia_bekas | AZ3: Catatan editor (bahasa awam) catatan_editor | BA3: Umur (tahun) · otomatis umur | BB3: Windows 11 resmi? · otomatis win11
A4: contoh-a14-i5-8-512 | B4: contoh-a14 | C4: A14-I5-8512 | D4: 2023 | E4: dijual | G4: Resmi Indonesia | H4: Tipis harian | I4: Pelajar dan pekerja kantoran | J4: Intel Core i5-1235U (CONTOH) | K4: Intel Iris Xe (CONTOH) | M4: 8 | N4: LPDDR4X | O4: 4266 | P4: dual | Q4: disolder | R4: 0 | S4: 0 | T4: 8 | U4: 8 | V4: 512 | W4: nvme_ssd | X4: PCIe 3.0 x4 | Y4: M.2 2280 | Z4: ya | AA4: 1 | AB4: 0 | AC4: tidak | AD4: terverifikasi | AE4: (contoh) manual servis resmi pabrikan | AF4: 1.4 | AG4: IPS | AH4: 1920x1080 | AI4: 60 | AJ4: tidak | AK4: 42 | AL4: 65 | AM4: Wi-Fi 6 | AN4: 5.2 | AO4: tidak | AP4: ya | AQ4: 720p | AR4: Windows 11 | AS4: Home | AT4: Home & Student (permanen) | AU4: Resmi Indonesia | AV4: 24 | AW4: 12 | AX4: ya | AY4: ya | AZ4: (CONTOH) RAM menempel di papan utama, jadi tidak bisa ditambah. Pilih ukuran yang cukup saat membeli. | BA4: =IF(D4="","",YEAR(TODAY())-D4) -> 3 | BB4: =IF(J4="","",IFERROR(IF(INDEX(CPU!$I$4:$I$64,MATCH(J4,CPU!$A$4:$A$64,0))="","(isi di tab CPU)",INDEX(CPU!$I$4:$I$64,MATCH(J4,CPU!$A$4:$A$64,0))),"(CPU belum ada di tab CPU)")) -> ya
A5: asus-m1405ya-r5-7430u-16-512 | B5: asus-m1405ya | C5: M1405YA-VIPS555 | E5: dijual | G5: Resmi Indonesia | H5: Vivobook (kategori Untuk Rumah) | J5: AMD Ryzen 5 7430U | K5: AMD Radeon Graphics (7 inti) | M5: 16 | N5: DDR4 | P5: dual | Q5: setengah_disolder | R5: 1 | S5: 0 | T5: 8 | U5: 16 | V5: 512 | W5: nvme_ssd | X5: PCIe 3.0 | Y5: M.2 2280 | Z5: ya | AA5: 1 | AB5: 0 | AC5: tidak | AD5: terverifikasi | AE5: ASUS techspec M1405: RAM 8 GB onboard + 8 GB SO-DIMM, maksimal 16 GB; 1 slot M.2 2280, hanya SSD satu sisi. https://asus.com/laptops/for-home/vivobook/asus-vivobook-14-oled-m1405/techspec | AF5: 1.6 | AG5: IPS | AH5: 1920x1200 | AI5: 60 | AJ5: tidak | AK5: 42 | AL5: 45 | AO5: ya | AP5: ya | AQ5: 720p | AR5: Windows 11 | AS5: Home | AT5: Home & Student (permanen) | AU5: Resmi Indonesia | AV5: 12 | AX5: ya | AY5: unknown | AZ5: RAM terdiri dari 8 GB yang menempel di papan utama dan 8 GB modul di slot. Hanya modul slot yang bisa diganti, dengan batas total 16 GB menurut ASUS. SSD harus yang satu sisi karena ada komponen di dekat slot M.2. | BA5: =IF(D5="","",YEAR(TODAY())-D5) | BB5: =IF(J5="","",IFERROR(IF(INDEX(CPU!$I$4:$I$64,MATCH(J5,CPU!$A$4:$A$64,0))="","(isi di tab CPU)",INDEX(CPU!$I$4:$I$64,MATCH(J5,CPU!$A$4:$A$64,0))),"(CPU belum ada di tab CPU)")) -> ya
A6: hp-pavilion-x360-14-ek1005tu-i5-1335u-16-512 | B6: hp-pavilion-x360-14 | C6: 14-ek1005TU (7N725PA) | D6: 2023 | E6: unknown | G6: Resmi Indonesia | H6: Pavilion (laptop pribadi) | J6: Intel Core i5-1335U | K6: Intel Iris Xe Graphics (80 EU) | M6: 16 | N6: DDR4 | O6: 3200 | Q6: disolder | R6: 0 | S6: 0 | T6: 16 | U6: 16 | V6: 512 | W6: nvme_ssd | X6: PCIe NVMe | Y6: unknown | Z6: ya | AC6: unknown | AD6: belum terverifikasi | AE6: RAM: halaman HP Indonesia ('16 GB DDR4-3200 MHz RAM (onboard)') dan Kingston (0 slot RAM, tidak bisa dilepas). SSD: bentuk M.2 dari HP; bisa diganti menurut forum HP untuk seri 14-ek0000; belum ada manual servis seri ini. https://hp.com/id-id/shop/hp-pavilion-x360-2-in-1-laptop-14-ek1005tu-7n725pa.html | AF6: 1.51 | AG6: IPS | AH6: 1920x1080 | AJ6: ya | AK6: 43 | AL6: 65 | AM6: Wi-Fi 6 | AN6: 5.3 | AO6: ya | AP6: ya | AQ6: 5 MP | AR6: Windows 11 | AS6: Single Language | AT6: Home & Student (permanen) | AU6: Resmi Indonesia | AV6: 24 | AX6: ya | AY6: unknown | AZ6: RAM 16 GB menempel di papan utama, jadi tidak bisa ditambah atau diganti. SSD berbentuk M.2; menurut forum HP bisa diganti selama SSD satu sisi, tetapi belum ada manual servis resmi untuk seri ini. | BA6: =IF(D6="","",YEAR(TODAY())-D6) -> 3 | BB6: =IF(J6="","",IFERROR(IF(INDEX(CPU!$I$4:$I$64,MATCH(J6,CPU!$A$4:$A$64,0))="","(isi di tab CPU)",INDEX(CPU!$I$4:$I$64,MATCH(J6,CPU!$A$4:$A$64,0))),"(CPU belum ada di tab CPU)")) -> ya
A7: axioo-hype-10-n4020-8-256-w11 | B7: axioo-hype-10 | C7: SLI-HY10-244C08HNR1 | E7: unknown | G7: Resmi Indonesia | H7: Hype (seri harga terjangkau) | I7: Generasi muda Indonesia (siaran pers Axioo, 15 November 2024) | J7: Intel Celeron N4020 | K7: Intel UHD Graphics 600 | M7: 8 | N7: DDR4 | O7: 2400 | P7: single | Q7: slot | R7: 1 | S7: 0 | T7: 0 | U7: 8 | V7: 256 | W7: sata_ssd | X7: SATA | Y7: M.2 2280 | Z7: ya | AA7: 2 | AC7: unknown | AD7: belum terverifikasi | AE7: Situs Axioo, halaman perbandingan Hype 1 Intel: 1x SODIMM DDR4 maksimal 8 GB; 2x M.2 2280 SATA. Halaman Poin Xtra untuk Hype 10 menulis 'SODIMM DDR4' dan memakai kalimat spesifikasi layar yang sama dengan situs Axioo, tetapi kesamaan Hype 10 dan Hype 1 Intel belum dikonfirmasi Axioo. https://axiooworld.com/product/compare/hype-1-intel/pongo-735 | AF7: 1.4 | AG7: TN | AH7: 1366x768 | AI7: 60 | AJ7: tidak | AK7: 38 | AR7: Windows 11 | AS7: unknown | AT7: unknown | AU7: Resmi Indonesia | AX7: ya | AY7: unknown | AZ7: RAM memakai satu modul di slot, jadi tidak ada slot kosong dan batasnya 8 GB. Ada dua slot M.2 SATA; jumlah yang masih kosong belum diketahui. Kedua port USB-C hanya untuk data. | BA7: =IF(D7="","",YEAR(TODAY())-D7) | BB7: =IF(J7="","",IFERROR(IF(INDEX(CPU!$I$4:$I$64,MATCH(J7,CPU!$A$4:$A$64,0))="","(isi di tab CPU)",INDEX(CPU!$I$4:$I$64,MATCH(J7,CPU!$A$4:$A$64,0))),"(CPU belum ada di tab CPU)")) -> ya
A8: axioo-hype-10-n4020-8-256-w10 | B8: axioo-hype-10 | C8: 244C08HNR0 | E8: unknown | G8: Resmi Indonesia | H8: Hype (seri harga terjangkau) | I8: Generasi muda Indonesia (siaran pers Axioo, 15 November 2024) | J8: Intel Celeron N4020 | K8: Intel UHD Graphics 600 | M8: 8 | N8: DDR4 | O8: 2400 | P8: single | Q8: slot | R8: 1 | S8: 0 | T8: 0 | U8: 8 | V8: 256 | W8: sata_ssd | X8: SATA | Y8: M.2 2280 | Z8: ya | AA8: 2 | AC8: unknown | AD8: belum terverifikasi | AE8: Situs Axioo, halaman perbandingan Hype 1 Intel: 1x SODIMM DDR4 maksimal 8 GB; 2x M.2 2280 SATA. Halaman Poin Xtra untuk Hype 10 menulis 'SODIMM DDR4' dan memakai kalimat spesifikasi layar yang sama dengan situs Axioo, tetapi kesamaan Hype 10 dan Hype 1 Intel belum dikonfirmasi Axioo. https://axiooworld.com/product/compare/hype-1-intel/pongo-735 | AF8: 1.4 | AG8: TN | AH8: 1366x768 | AJ8: tidak | AK8: 38 | AM8: Wi-Fi 5 | AN8: 5.1 | AR8: Windows 10 | AS8: unknown | AT8: unknown | AU8: Resmi Indonesia | AV8: 12 | AX8: ya | AY8: unknown | AZ8: Versi dengan Windows 10. Dukungan resmi Windows 10 berakhir pada 14 Oktober 2025, sedangkan prosesor N4020 termasuk dalam daftar resmi Windows 11. | BA8: =IF(D8="","",YEAR(TODAY())-D8) | BB8: =IF(J8="","",IFERROR(IF(INDEX(CPU!$I$4:$I$64,MATCH(J8,CPU!$A$4:$A$64,0))="","(isi di tab CPU)",INDEX(CPU!$I$4:$I$64,MATCH(J8,CPU!$A$4:$A$64,0))),"(CPU belum ada di tab CPU)")) -> ya
A9: lenovo-thinkpad-t480-i5-8350u-8-256 | B9: lenovo-thinkpad-t480 | C9: (bekas, tanpa kode seragam) | D9: 2018 | E9: bekas_saja | G9: unknown | H9: ThinkPad seri T | J9: Intel Core i5-8350U | K9: Intel UHD Graphics 620 | M9: 8 | N9: DDR4 | O9: 2400 | P9: unknown | Q9: slot | R9: 2 | T9: 0 | U9: 32 | V9: 256 | W9: unknown | X9: unknown | Y9: unknown | Z9: ya | AA9: 1 | AC9: tidak | AD9: terverifikasi | AE9: Lenovo PSREF T480: 2 slot SO-DIMM DDR4, maksimal 32 GB; satu slot HDD 2,5 inci atau satu slot M.2 2280 untuk penyimpanan utama. Windows Central: RAM dan penyimpanan bisa diganti lewat panel belakang. https://psref.lenovo.com/syspool/Sys/PDF/ThinkPad/ThinkPad_T480/ThinkPad_T480_Spec.PDF | AF9: 1.58 | AG9: unknown | AH9: unknown | AJ9: unknown | AM9: Wi-Fi 5 | AN9: 4.1 | AO9: unknown | AP9: unknown | AQ9: 720p | AR9: unknown | AS9: unknown | AT9: unknown | AU9: Toko | AX9: unknown | AY9: ya | AZ9: RAM memakai dua slot SO-DIMM dan bisa sampai 32 GB. Menurut Lenovo, penyimpanan utama memakai satu slot hard disk 2,5 inci atau satu slot M.2 2280, tidak keduanya sekaligus. Bobot resmi 1,58-1,87 kg tergantung baterai dan layar. Konfigurasi bekas berbeda tiap penjual: cek tipe SSD, layar, dan kondisi baterai. | BA9: =IF(D9="","",YEAR(TODAY())-D9) -> 8 | BB9: =IF(J9="","",IFERROR(IF(INDEX(CPU!$I$4:$I$64,MATCH(J9,CPU!$A$4:$A$64,0))="","(isi di tab CPU)",INDEX(CPU!$I$4:$I$64,MATCH(J9,CPU!$A$4:$A$64,0))),"(CPU belum ada di tab CPU)")) -> ya
A10: lenovo-thinkpad-t480-i5-8350u-16-512 | B10: lenovo-thinkpad-t480 | C10: (bekas, tanpa kode seragam) | D10: 2018 | E10: bekas_saja | G10: unknown | H10: ThinkPad seri T | J10: Intel Core i5-8350U | K10: Intel UHD Graphics 620 | M10: 16 | N10: DDR4 | O10: 2400 | P10: unknown | Q10: slot | R10: 2 | T10: 0 | U10: 32 | V10: 512 | W10: unknown | X10: unknown | Y10: unknown | Z10: ya | AA10: 1 | AC10: tidak | AD10: terverifikasi | AE10: Lenovo PSREF T480: 2 slot SO-DIMM DDR4, maksimal 32 GB; satu slot HDD 2,5 inci atau satu slot M.2 2280 untuk penyimpanan utama. Windows Central: RAM dan penyimpanan bisa diganti lewat panel belakang. https://psref.lenovo.com/syspool/Sys/PDF/ThinkPad/ThinkPad_T480/ThinkPad_T480_Spec.PDF | AF10: 1.58 | AG10: unknown | AH10: unknown | AJ10: unknown | AM10: Wi-Fi 5 | AN10: 4.1 | AO10: unknown | AP10: unknown | AQ10: 720p | AR10: unknown | AS10: unknown | AT10: unknown | AU10: Toko | AX10: unknown | AY10: ya | AZ10: Sama seperti T480 8/256, tetapi RAM 16 GB dan penyimpanan 512 GB. Bobot resmi 1,58-1,87 kg tergantung baterai dan layar. Cek tipe SSD, layar, dan kondisi baterai sebelum membeli. | BA10: =IF(D10="","",YEAR(TODAY())-D10) -> 8 | BB10: =IF(J10="","",IFERROR(IF(INDEX(CPU!$I$4:$I$64,MATCH(J10,CPU!$A$4:$A$64,0))="","(isi di tab CPU)",INDEX(CPU!$I$4:$I$64,MATCH(J10,CPU!$A$4:$A$64,0))),"(CPU belum ada di tab CPU)")) -> ya
A11: dell-latitude-5400-i5-8265u-8-256 | B11: dell-latitude-5400 | C11: (bekas, tanpa kode seragam) | D11: 2019 | E11: bekas_saja | G11: unknown | H11: Latitude seri 5000 | J11: Intel Core i5-8265U | K11: Intel UHD Graphics 620 | M11: 8 | N11: DDR4 | O11: 2400 | P11: unknown | Q11: slot | R11: 2 | T11: 0 | U11: 32 | V11: 256 | W11: unknown | X11: unknown | Y11: unknown | Z11: ya | AA11: 1 | AC11: unknown | AD11: terverifikasi | AE11: Dell Latitude 5400 (panduan spesifikasi dan manual servis): 2 slot SoDIMM DDR4, maksimal 32 GB; 1 slot M.2 (2230 atau 2280); ruang hard disk 2,5 inci tidak bisa dipakai pada baterai 4-sel. LaptopMedia (ulasan 6 Agustus 2019): 2 slot RAM dan slot M.2 NVMe. https://www.dell.com/support/product-details/en-us/product/latitude-14-5400-laptop/resources/manuals | AF11: 1.48 | AG11: unknown | AH11: unknown | AJ11: unknown | AO11: unknown | AP11: unknown | AR11: unknown | AS11: unknown | AT11: unknown | AU11: Toko | AX11: unknown | AY11: ya | AZ11: Dua slot RAM (maksimal 32 GB) dan satu slot M.2. Bila baterainya 4-sel (68 Wh), ruang hard disk 2,5 inci tidak bisa dipakai. Konfigurasi bekas berbeda tiap penjual: cek tipe SSD, layar, dan kondisi baterai. | BA11: =IF(D11="","",YEAR(TODAY())-D11) -> 7 | BB11: =IF(J11="","",IFERROR(IF(INDEX(CPU!$I$4:$I$64,MATCH(J11,CPU!$A$4:$A$64,0))="","(isi di tab CPU)",INDEX(CPU!$I$4:$I$64,MATCH(J11,CPU!$A$4:$A$64,0))),"(CPU belum ada di tab CPU)")) -> ya
A12: dell-latitude-5400-i5-8365u-8-256 | B12: dell-latitude-5400 | C12: (bekas, tanpa kode seragam) | D12: 2019 | E12: bekas_saja | G12: unknown | H12: Latitude seri 5000 | J12: Intel Core i5-8365U | K12: Intel UHD Graphics 620 | M12: 8 | N12: DDR4 | O12: 2400 | P12: unknown | Q12: slot | R12: 2 | T12: 0 | U12: 32 | V12: 256 | W12: unknown | X12: unknown | Y12: unknown | Z12: ya | AA12: 1 | AC12: unknown | AD12: terverifikasi | AE12: Dell Latitude 5400 (panduan spesifikasi dan manual servis): 2 slot SoDIMM DDR4, maksimal 32 GB; 1 slot M.2 (2230 atau 2280); ruang hard disk 2,5 inci tidak bisa dipakai pada baterai 4-sel. LaptopMedia (ulasan 6 Agustus 2019): 2 slot RAM dan slot M.2 NVMe. https://www.dell.com/support/product-details/en-us/product/latitude-14-5400-laptop/resources/manuals | AF12: 1.48 | AG12: unknown | AH12: unknown | AJ12: unknown | AO12: unknown | AP12: unknown | AR12: unknown | AS12: unknown | AT12: unknown | AU12: Toko | AX12: unknown | AY12: ya | AZ12: Sama seperti Latitude 5400 i5-8265U, tetapi prosesornya i5-8365U yang mendukung vPro (fitur pengelolaan jarak jauh untuk kantor). Bila baterainya 4-sel (68 Wh), ruang hard disk 2,5 inci tidak bisa dipakai. | BA12: =IF(D12="","",YEAR(TODAY())-D12) -> 7 | BB12: =IF(J12="","",IFERROR(IF(INDEX(CPU!$I$4:$I$64,MATCH(J12,CPU!$A$4:$A$64,0))="","(isi di tab CPU)",INDEX(CPU!$I$4:$I$64,MATCH(J12,CPU!$A$4:$A$64,0))),"(CPU belum ada di tab CPU)")) -> ya
BA13: =IF(D13="","",YEAR(TODAY())-D13) | BB13: =IF(J13="","",IFERROR(IF(INDEX(CPU!$I$4:$I$64,MATCH(J13,CPU!$A$4:$A$64,0))="","(isi di tab CPU)",INDEX(CPU!$I$4:$I$64,MATCH(J13,CPU!$A$4:$A$64,0))),"(CPU belum ada di tab CPU)"))
BA14: =IF(D14="","",YEAR(TODAY())-D14) | BB14: =IF(J14="","",IFERROR(IF(INDEX(CPU!$I$4:$I$64,MATCH(J14,CPU!$A$4:$A$64,0))="","(isi di tab CPU)",INDEX(CPU!$I$4:$I$64,MATCH(J14,CPU!$A$4:$A$64,0))),"(CPU belum ada di tab CPU)"))
BA15: =IF(D15="","",YEAR(TODAY())-D15) | BB15: =IF(J15="","",IFERROR(IF(INDEX(CPU!$I$4:$I$64,MATCH(J15,CPU!$A$4:$A$64,0))="","(isi di tab CPU)",INDEX(CPU!$I$4:$I$64,MATCH(J15,CPU!$A$4:$A$64,0))),"(CPU belum ada di tab CPU)"))
BA16: =IF(D16="","",YEAR(TODAY())-D16) | BB16: =IF(J16="","",IFERROR(IF(INDEX(CPU!$I$4:$I$64,MATCH(J16,CPU!$A$4:$A$64,0))="","(isi di tab CPU)",INDEX(CPU!$I$4:$I$64,MATCH(J16,CPU!$A$4:$A$64,0))),"(CPU belum ada di tab CPU)"))
BA17: =IF(D17="","",YEAR(TODAY())-D17) | BB17: =IF(J17="","",IFERROR(IF(INDEX(CPU!$I$4:$I$64,MATCH(J17,CPU!$A$4:$A$64,0))="","(isi di tab CPU)",INDEX(CPU!$I$4:$I$64,MATCH(J17,CPU!$A$4:$A$64,0))),"(CPU belum ada di tab CPU)"))
BA18: =IF(D18="","",YEAR(TODAY())-D18) | BB18: =IF(J18="","",IFERROR(IF(INDEX(CPU!$I$4:$I$64,MATCH(J18,CPU!$A$4:$A$64,0))="","(isi di tab CPU)",INDEX(CPU!$I$4:$I$64,MATCH(J18,CPU!$A$4:$A$64,0))),"(CPU belum ada di tab CPU)"))
BA19: =IF(D19="","",YEAR(TODAY())-D19) | BB19: =IF(J19="","",IFERROR(IF(INDEX(CPU!$I$4:$I$64,MATCH(J19,CPU!$A$4:$A$64,0))="","(isi di tab CPU)",INDEX(CPU!$I$4:$I$64,MATCH(J19,CPU!$A$4:$A$64,0))),"(CPU belum ada di tab CPU)"))
BA20: =IF(D20="","",YEAR(TODAY())-D20) | BB20: =IF(J20="","",IFERROR(IF(INDEX(CPU!$I$4:$I$64,MATCH(J20,CPU!$A$4:$A$64,0))="","(isi di tab CPU)",INDEX(CPU!$I$4:$I$64,MATCH(J20,CPU!$A$4:$A$64,0))),"(CPU belum ada di tab CPU)"))
BA21: =IF(D21="","",YEAR(TODAY())-D21) | BB21: =IF(J21="","",IFERROR(IF(INDEX(CPU!$I$4:$I$64,MATCH(J21,CPU!$A$4:$A$64,0))="","(isi di tab CPU)",INDEX(CPU!$I$4:$I$64,MATCH(J21,CPU!$A$4:$A$64,0))),"(CPU belum ada di tab CPU)"))
BA22: =IF(D22="","",YEAR(TODAY())-D22) | BB22: =IF(J22="","",IFERROR(IF(INDEX(CPU!$I$4:$I$64,MATCH(J22,CPU!$A$4:$A$64,0))="","(isi di tab CPU)",INDEX(CPU!$I$4:$I$64,MATCH(J22,CPU!$A$4:$A$64,0))),"(CPU belum ada di tab CPU)"))
BA23: =IF(D23="","",YEAR(TODAY())-D23) | BB23: =IF(J23="","",IFERROR(IF(INDEX(CPU!$I$4:$I$64,MATCH(J23,CPU!$A$4:$A$64,0))="","(isi di tab CPU)",INDEX(CPU!$I$4:$I$64,MATCH(J23,CPU!$A$4:$A$64,0))),"(CPU belum ada di tab CPU)"))
BA24: =IF(D24="","",YEAR(TODAY())-D24) | BB24: =IF(J24="","",IFERROR(IF(INDEX(CPU!$I$4:$I$64,MATCH(J24,CPU!$A$4:$A$64,0))="","(isi di tab CPU)",INDEX(CPU!$I$4:$I$64,MATCH(J24,CPU!$A$4:$A$64,0))),"(CPU belum ada di tab CPU)"))
... BA64: =IF(D64="","",YEAR(TODAY())-D64) | BB64: =IF(J64="","",IFERROR(IF(INDEX(CPU!$I$4:$I$64,MATCH(J64,CPU!$A$4:$A$64,0))="","(isi di tab CPU)",INDEX(CPU!$I$4:$I$64,MATCH(J64,CPU!$A$4:$A$64,0))),"(CPU belum ada di tab CPU)"))

Sheet CPU
A1: CPU: satu baris untuk satu prosesor
A2: Tingkat 1-5 adalah penilaian kita sendiri (usulan awal); alasannya wajib diisi. Tab Varian memilih CPU dari sini.
A3: Nama prosesor nama | B3: Produsen produsen | C3: Generasi / seri generasi | D3: Nama kode kode | E3: Tahun rilis tahun | F3: Jumlah inti core | G3: Jumlah thread thread | H3: Kelas daya kelas | I3: Resmi Windows 11? win11 | J3: Tingkat (1-5) tier | K3: Alasan tingkat alasan | L3: Penjelasan bahasa awam awam | M3: Sumber sumber | N3: Tanggal diperiksa tgl
A4: Intel Core i5-1235U (CONTOH) | B4: Intel | C4: Core generasi ke-12 | D4: Alder Lake | E4: 2022 | F4: 10 | G4: 12 | H4: hemat | I4: ya | J4: 3 | K4: (CONTOH) Cukup untuk kuliah dan kerja kantoran; kurang untuk render video berat. | L4: (CONTOH) Otak laptop yang kuat untuk pekerjaan harian. | M4: (contoh) situs resmi Intel | N4: 46303
A5: AMD Ryzen 5 7430U | B5: AMD | C5: Ryzen 5 seri 7000 (U) | D5: Barcelo-R | E5: 2023 | F5: 6 | G5: 12 | H5: hemat | I5: ya | J5: 3 | K5: 6 inti 12 thread, boost sampai 4,3 GHz, daya 15 W. Cukup untuk kuliah, kerja kantoran, dan banyak tab terbuka; masih di bawah prosesor kelas 45 W untuk render atau kompilasi berat. | L5: Otak laptop kelas menengah dengan 6 inti. Bisa mengerjakan beberapa hal sekaligus dengan lancar dan tetap hemat baterai. | M5: AMD: https://www.amd.com/en/products/processors/laptop/ryzen/7000-series/amd-ryzen-5-7430u.html (daftar sistem operasi yang didukung memuat Windows 11). Prosesor ini tidak ada di daftar AMD milik Microsoft, tetapi ASUS menjual M1405YA dengan Windows 11. | N5: 46303
A6: Intel Core i5-1335U | B6: Intel | C6: Core generasi ke-13 | D6: Raptor Lake | E6: 2023 | F6: 10 | G6: 12 | H6: hemat | I6: ya | J6: 3 | K6: 10 inti (2 inti performa + 8 inti hemat) 12 thread, turbo sampai 4,6 GHz, daya dasar 15 W. Lancar untuk kuliah dan kerja kantoran; kurang untuk render atau kompilasi besar. | L6: Otak laptop kelas menengah generasi ke-13. Cepat untuk pekerjaan harian dan tetap hemat baterai. | M6: Intel ARK: https://www.intel.com/content/www/us/en/products/sku/232153/specifications.html Windows 11: https://learn.microsoft.com/en-us/windows-hardware/design/minimum/supported/windows-11-supported-intel-processors (baris 13th Generation Core i5). | N6: 46303
A7: Intel Celeron N4020 | B7: Intel | C7: Celeron N4000 | D7: Gemini Lake Refresh | E7: 2019 | F7: 2 | G7: 2 | H7: hemat | I7: ya | J7: 1 | K7: 2 inti 2 thread, kecepatan dasar 1,1 GHz (burst 2,8 GHz), daya 6 W, RAM maksimal 8 GB. Cukup untuk dokumen dan internet ringan; terasa lambat bila banyak tab atau aplikasi dibuka sekaligus. | L7: Otak laptop paling sederhana. Hemat daya, tetapi mudah kewalahan kalau banyak yang dibuka sekaligus. | M7: Intel ARK: https://www.intel.com/content/www/us/en/products/sku/197310/specifications.html Windows 11: https://learn.microsoft.com/en-us/windows-hardware/design/minimum/supported/windows-11-supported-intel-processors (baris Celeron N4000 Series). | N7: 46303
A8: Intel Core i5-8350U | B8: Intel | C8: Core generasi ke-8 | D8: Kaby Lake R | E8: 2017 | F8: 4 | G8: 8 | H8: hemat | I8: ya | J8: 2 | K8: 4 inti 8 thread (1,7 GHz dasar, 3,6 GHz turbo), daya 15 W. Cukup untuk dokumen, internet, dan kuliah; intinya lebih sedikit dan lebih tua daripada prosesor generasi ke-13 (i5-1335U: 10 inti). | L8: Otak laptop kelas menengah dari generasi lama (2017). Masih cukup untuk tugas harian, tetapi lebih lambat daripada prosesor baru. | M8: Intel ARK: https://www.intel.com/content/www/us/en/products/sku/124969/specifications.html Windows 11: https://learn.microsoft.com/en-us/windows-hardware/design/minimum/supported/windows-11-supported-intel-processors (baris 8th Generation Core i5). | N8: 46303
A9: Intel Core i5-8265U | B9: Intel | C9: Core generasi ke-8 | D9: Whiskey Lake | E9: 2018 | F9: 4 | G9: 8 | H9: hemat | I9: ya | J9: 2 | K9: 4 inti 8 thread (1,6 GHz dasar, 3,9 GHz turbo), daya 15 W. Cukup untuk dokumen, internet, dan kuliah; intinya lebih sedikit dan lebih tua daripada prosesor generasi ke-13. | L9: Otak laptop kelas menengah dari generasi lama (2018). Masih cukup untuk tugas harian, tetapi lebih lambat daripada prosesor baru. | M9: Intel ARK: https://www.intel.com/content/www/us/en/products/sku/149088/specifications.html Windows 11: https://learn.microsoft.com/en-us/windows-hardware/design/minimum/supported/windows-11-supported-intel-processors (baris 8th Generation Core i5). | N9: 46303
A10: Intel Core i5-8365U | B10: Intel | C10: Core generasi ke-8 | D10: Whiskey Lake | E10: 2019 | F10: 4 | G10: 8 | H10: hemat | I10: ya | J10: 2 | K10: 4 inti 8 thread (1,6 GHz dasar, 4,1 GHz turbo), daya 15 W, mendukung vPro. Cukup untuk dokumen, internet, dan kuliah; intinya lebih sedikit dan lebih tua daripada prosesor generasi ke-13. | L10: Otak laptop kelas menengah dari generasi lama (2019), dengan fitur pengelolaan jarak jauh untuk kantor (vPro). Masih cukup untuk tugas harian. | M10: Intel ARK: https://www.intel.com/content/www/us/en/products/sku/193555/intel-core-i58365u-processor-6m-cache-up-to-4-10-ghz/specifications.html Windows 11: https://learn.microsoft.com/en-us/windows-hardware/design/minimum/supported/windows-11-supported-intel-processors (baris 8th Generation Core i5). | N10: 46303

Sheet GPU
A1: GPU: satu baris untuk satu kartu grafis
A2: Grafis bawaan juga ditulis di sini. Tingkat 1-5 adalah penilaian kita sendiri (usulan awal); alasannya wajib diisi.
A3: Nama kartu grafis nama | B3: Produsen produsen | C3: Jenis jenis | D3: Arsitektur arsitektur | E3: Tahun rilis tahun | F3: VRAM (GB, isi 0 bila bawaan) vram | G3: Tingkat (1-5) tier | H3: Alasan tingkat alasan | I3: Penjelasan bahasa awam awam | J3: Sumber sumber | K3: Tanggal diperiksa tgl
A4: Intel Iris Xe (CONTOH) | B4: Intel | C4: bawaan | D4: Xe-LP | E4: 2020 | F4: 0 | G4: 2 | H4: (CONTOH) Cukup untuk video dan game ringan; tidak untuk game berat. | I4: (CONTOH) Pengolah gambar yang menyatu dengan CPU dan berbagi memori dengan RAM. | J4: (contoh) situs resmi Intel | K4: 46303
A5: AMD Radeon Graphics (7 inti) | B5: AMD | C5: bawaan | F5: 0 | G5: 2 | H5: Grafis bawaan Ryzen 5 7430U dengan 7 inti grafis (1800 MHz), berbagi memori dengan RAM. Cukup untuk video, desain ringan, dan game ringan. | I5: Pengolah gambar yang menyatu dengan prosesor dan memakai sebagian memori RAM. Cukup untuk menonton video, desain ringan, dan game ringan. | J5: AMD: https://www.amd.com/en/products/processors/laptop/ryzen/7000-series/amd-ryzen-5-7430u.html | K5: 46303
A6: Intel Iris Xe Graphics (80 EU) | B6: Intel | C6: bawaan | F6: 0 | G6: 2 | H6: Grafis bawaan i5-1335U dengan 80 unit eksekusi, berbagi memori dengan RAM. Cukup untuk video, desain ringan, dan game ringan. | I6: Pengolah gambar yang menyatu dengan prosesor dan memakai sebagian memori RAM. Cukup untuk menonton video, desain ringan, dan game ringan. | J6: Intel ARK: https://www.intel.com/content/www/us/en/products/sku/232153/specifications.html | K6: 46303
A7: Intel UHD Graphics 600 | B7: Intel | C7: bawaan | F7: 0 | G7: 1 | H7: Grafis bawaan paling dasar pada Celeron N4020, tanpa kartu grafis terpisah. Untuk tampilan, dokumen, dan video biasa. | I7: Pengolah gambar paling dasar yang menyatu dengan prosesor. Cukup untuk tampilan, dokumen, dan menonton video; tidak untuk game berat. | J7: Intel ARK: https://www.intel.com/content/www/us/en/products/sku/197310/specifications.html | K7: 46303
A8: Intel UHD Graphics 620 | B8: Intel | C8: bawaan | F8: 0 | G8: 1 | H8: Grafis bawaan prosesor Core generasi ke-8, tanpa kartu grafis terpisah. Untuk tampilan, dokumen, dan video biasa. | I8: Pengolah gambar dasar yang menyatu dengan prosesor. Cukup untuk tampilan, dokumen, dan menonton video; tidak untuk game berat. | J8: Intel ARK: https://www.intel.com/content/www/us/en/products/sku/124969/specifications.html; Dell Latitude 5400: UHD Graphics 620 bawaan (atau AMD Radeon 540X pada konfigurasi tertentu) | K8: 46303

Sheet Harga
A1: Harga: satu baris untuk satu pengamatan harga pada satu tanggal
A2: Jangan menimpa harga lama; tambahkan baris baru setiap kali harga dicek, supaya riwayatnya terlihat.
A3: ID varian id_varian | B3: Kondisi kondisi | C3: Harga terendah (Rp) hmin | D3: Harga tertinggi (Rp) hmaks | E3: Harga tengah (Rp) · otomatis tengah | F3: Jenis sumber jenis_sumber | G3: Sumber (tautan atau nama toko) sumber | H3: Tanggal dicek tgl | I3: Catatan catatan
A4: contoh-a14-i5-8-512 | B4: baru | C4: 7000000 | D4: 7500000 | E4: =IF(OR(C4="",D4=""),"",(C4+D4)/2) -> 7250000 | F4: marketplace | G4: (contoh) halaman pencarian marketplace | H4: 46303 | I4: (CONTOH) Rentang dari lima penjual teratas.
A5: asus-m1405ya-r5-7430u-16-512 | B5: baru | C5: 8839000 | D5: 8839000 | E5: =IF(OR(C5="",D5=""),"",(C5+D5)/2) -> 8839000 | F5: marketplace | G5: https://poinxtra.cimbniaga.co.id/TD/29907030/Asus-Vivobook-14-Ryzen-5-7430U-16-512GB-Cool-Silver-M1405YA-VIPS555 | H5: 46303 | I5: Poin Xtra CIMB Niaga. Harga daftar Rp8.999.000. Stok habis saat dicek.
A6: asus-m1405ya-r5-7430u-16-512 | B6: baru | C6: 8590000 | D6: 8590000 | E6: =IF(OR(C6="",D6=""),"",(C6+D6)/2) -> 8590000 | F6: marketplace | G6: https://ekatalog.its.ac.id/shop/product/asus-m1405ya-vips555-non-tkdn-5972?page=3 | H6: 46303 | I6: Katalog pengadaan ITS. Penjual: PT Megastar Electronics. Stok tidak tertulis.
A7: asus-m1405ya-r5-7430u-16-512 | B7: baru | C7: 8039000 | D7: 8039000 | E7: =IF(OR(C7="",D7=""),"",(C7+D7)/2) -> 8039000 | F7: marketplace | G7: https://www.tokopedia.com/decacom/asus-vivobook-14-oled-m1405ya-ryzen-7-7730u-ryzen-5-7430u-16gb-512ssd-1tb-w11-ohs-1730850621135292383 | H7: 46303 | I7: Tokopedia, toko decacom, pilihan Ryzen 5 16GB/512GB. Harga coret Rp9.199.000. Stok 83 unit.
A8: asus-m1405ya-r5-7430u-16-512 | B8: baru | C8: 7729000 | D8: 9394000 | E8: =IF(OR(C8="",D8=""),"",(C8+D8)/2) -> 8561500 | F8: marketplace | G8: https://www.tokopedia.com/find/asus-vivobook-14-m1405ya-ryzen-5-7430u-16gb-512gb | H8: 46303 | I8: Hasil pencarian Tokopedia. Enam dari sepuluh listing dipakai (tiga di antaranya sama di Rp7.729.000). Empat listing Rp15,8-26,6 juta tidak dipakai karena jauh di atas harga toko lain.
A9: hp-pavilion-x360-14-ek1005tu-i5-1335u-16-512 | B9: baru | C9: 13499000 | D9: 13499000 | E9: =IF(OR(C9="",D9=""),"",(C9+D9)/2) -> 13499000 | F9: toko_resmi | G9: https://hp.com/id-id/shop/hp-pavilion-x360-2-in-1-laptop-14-ek1005tu-7n725pa.html | H9: 46303 | I9: Toko resmi HP Indonesia. Status 'Kehabisan persediaan' saat dicek.
A10: hp-pavilion-x360-14-ek1005tu-i5-1335u-16-512 | B10: baru | C10: 17365000 | D10: 17365000 | E10: =IF(OR(C10="",D10=""),"",(C10+D10)/2) -> 17365000 | F10: marketplace | G10: https://www.tokopedia.com/find/laptop-hp-pavilion-x360-core-i5-1335u-16gb-512gb | H10: 46303 | I10: Tokopedia, penjual Raharja Notebook (Malang). Stok tidak tertulis. Satu listing lain di Rp8.500.000 tidak dipakai karena judulnya memuat kode model yang tidak cocok (ek100STU).
A11: axioo-hype-10-n4020-8-256-w11 | B11: baru | C11: 4799000 | D11: 4799000 | E11: =IF(OR(C11="",D11=""),"",(C11+D11)/2) -> 4799000 | F11: toko_resmi | G11: https://www.erablue.id/laptop/laptop-axioo-slimbook-hype-10-celeron-n4020-8gb-256gb-win11-midnight-black | H11: 46303 | I11: Erablue. Harga coret Rp5.299.000; promo sampai 31/10. Stok tidak tertulis.
A12: axioo-hype-10-n4020-8-256-w11 | B12: baru | C12: 5459000 | D12: 5499000 | E12: =IF(OR(C12="",D12=""),"",(C12+D12)/2) -> 5479000 | F12: marketplace | G12: https://www.tokopedia.com/find/axioo-hype-10 | H12: 46303 | I12: Hasil pencarian Tokopedia, dua listing Windows 11 (SOFTCOM Official Store Rp5.459.000; HOSANA COMPUTER Rp5.499.000). Lima listing Rp7.999.000-Rp14.099.000 di halaman yang sama tidak dipakai karena jauh di atas harga toko lain.
A13: axioo-hype-10-n4020-8-256-w10 | B13: baru | C13: 3099000 | D13: 3099000 | E13: =IF(OR(C13="",D13=""),"",(C13+D13)/2) -> 3099000 | F13: marketplace | G13: https://poinxtra.cimbniaga.co.id/TD/29772632/AXIOO-HYPE-10-N4020-8GB-256GB-W10-14-0-244C08HNR0-MIDNIGHT-BLACK | H13: 46303 | I13: Poin Xtra CIMB Niaga. Harga daftar Rp6.199.000. Stok habis saat dicek.
A14: axioo-hype-10-n4020-8-256-w10 | B14: baru | C14: 4849000 | D14: 4909000 | E14: =IF(OR(C14="",D14=""),"",(C14+D14)/2) -> 4879000 | F14: marketplace | G14: https://www.tokopedia.com/find/axioo-hype-10 | H14: 46303 | I14: Hasil pencarian Tokopedia, dua listing Windows 10 (GO LAPTOP JAKARTA Rp4.849.000, Windows 10 Pro; ROYAL COM Rp4.909.000).
A15: lenovo-thinkpad-t480-i5-8350u-8-256 | B15: bekas | C15: 3150000 | D15: 4163000 | E15: =IF(OR(C15="",D15=""),"",(C15+D15)/2) -> 3656500 | F15: marketplace | G15: https://www.tokopedia.com/find/thinkpad-t480-i5-8350u-8gb-256gb | H15: 46303 | I15: Hasil pencarian Tokopedia. Enam listing i5-8350U 8GB/256GB tanpa kata 'sentuh' (median Rp3.500.000). Tiga listing layar sentuh (Rp3.435.000-Rp4.718.000) dan satu listing 'RAM 8GB/16GB' tidak dihitung.
... A19: dell-latitude-5400-i5-8365u-8-256 | B19: bekas | C19: 3500000 | D19: 4212000 | E19: =IF(OR(C19="",D19=""),"",(C19+D19)/2) -> 3856000 | F19: marketplace | G19: https://www.tokopedia.com/find/dell-latitude-5400-i5-8365u-8gb-256gb | H19: 46303 | I19: Hasil pencarian Tokopedia, empat listing tanpa kata 'sentuh' (Rp3.500.000; Rp3.550.000; Rp3.650.000; Rp4.212.000 dengan NVMe dan layar IPS FHD). Dua listing layar sentuh (Rp3.447.000) tidak dihitung.
E20: =IF(OR(C20="",D20=""),"",(C20+D20)/2)
E21: =IF(OR(C21="",D21=""),"",(C21+D21)/2)
E22: =IF(OR(C22="",D22=""),"",(C22+D22)/2)
E23: =IF(OR(C23="",D23=""),"",(C23+D23)/2)
E24: =IF(OR(C24="",D24=""),"",(C24+D24)/2)
E25: =IF(OR(C25="",D25=""),"",(C25+D25)/2)
E26: =IF(OR(C26="",D26=""),"",(C26+D26)/2)
E27: =IF(OR(C27="",D27=""),"",(C27+D27)/2)
E28: =IF(OR(C28="",D28=""),"",(C28+D28)/2)
E29: =IF(OR(C29="",D29=""),"",(C29+D29)/2)
E30: =IF(OR(C30="",D30=""),"",(C30+D30)/2)
E31: =IF(OR(C31="",D31=""),"",(C31+D31)/2)
... E64: =IF(OR(C64="",D64=""),"",(C64+D64)/2)

Sheet Catatan Pengisian
A1: Catatan pengisian: lima laptop awal
A2: Sumber, hambatan, dan temuan untuk tiap laptop. Isian awal dikerjakan dari situs pabrikan dan situs besar pada 8 Oktober 2026. Kolom waktu diisi saat kamu memeriksa ulang datanya.
A3: Laptop · otomatis | B3: Peran · otomatis | C3: Waktu pemeriksaan (menit) | D3: Kolom yang sulit dicari | E3: Sumber yang dipakai | F3: Kolom yang akhirnya unknown | G3: Temuan penting
A4: =IF(Model!C5="","",Model!B5&" "&Model!C5) -> ASUS Vivobook 14 M1405YA | B4: =IF(Model!D5="","",Model!D5) -> Baru populer | D4: Tahun rilis varian. Tipe Wi-Fi dan Bluetooth (ASUS memuat dua pilihan tanpa menyebut varian). Kecepatan RAM tidak ditulis ASUS. | E4: ASUS techspec M1405 (RAM, penyimpanan, layar, port, baterai). The FPS Review, 10 Februari 2023 (pengumuman seri M1405). Poin Xtra CIMB, e-katalog ITS, dan Tokopedia (kode varian, harga). AMD (7430U). Daftar Windows 11 milik Microsoft. | F4: Tahun rilis varian (tahun seri 2023 dari pengumuman ASUS), kecepatan RAM, Wi-Fi, Bluetooth, bahan bodi, kemampuan USB-C, isi daya lewat USB-C. | G4: RAM setengah menempel: 8 GB di papan utama ditambah 1 slot, maksimal 16 GB. SSD hanya cocok yang satu sisi (catatan resmi ASUS). Prosesor 7430U tidak ada di daftar AMD milik Microsoft, tetapi AMD mencantumkan Windows 11 dan ASUS menjual laptop ini dengan Windows 11. Di Tokopedia, 4 dari 10 listing berharga Rp15,8-26,6 juta (tidak dipakai).
A5: =IF(Model!C6="","",Model!B6&" "&Model!C6) -> HP Pavilion x360 14-ek1000 | B5: =IF(Model!D6="","",Model!D6) -> Baru tipis atau 2-in-1 | D5: Manual servis seri ek1000 tidak ditemukan. Halaman dukungan HP butuh JavaScript sehingga tidak terbaca. Halaman produk ek2333TU dan ek0160TU di HP Indonesia hanya mengarah ke daftar toko. | E5: Halaman produk HP Indonesia 14-ek1005TU (spesifikasi, harga, stok). Kingston (slot RAM). Forum HP (seri ek0000, SSD). Notebookcheck (ek1000ng, pembanding). Intel ARK (i5-1335U). Tokopedia (harga). | F5: Bentuk SSD (2280 atau lain), jumlah slot M.2, bisa tidaknya SSD diganti (belum ada manual servis), channel RAM, refresh rate, bahan bodi, isi daya lewat USB-C, status penjualan. | G5: RAM 16 GB menempel (HP menulis 'onboard'; Kingston: 0 slot). Toko resmi HP Indonesia kehabisan stok saat dicek (Rp13.499.000). Tokopedia: Rp17.365.000 dari satu penjual; listing Rp8.500.000 diabaikan karena kode modelnya tidak cocok. Tahun rilis 2023 adalah perkiraan dari tahun rilis prosesor (Q1 2023).
A6: =IF(Model!C7="","",Model!B7&" "&Model!C7) -> Axioo Hype 10 | B6: =IF(Model!D7="","",Model!D7) -> Merek lokal | D6: Nama Hype 10 tidak ada di daftar produk situs Axioo. Spesifikasi resmi hanya ditemukan di halaman perbandingan Hype 1 Intel, yang tidak memuat bobot, baterai, Wi-Fi, Bluetooth, dan charger. | E6: Situs Axioo (halaman perbandingan Hype 1 Intel; siaran pers 15 November 2024). Erablue (spesifikasi dan harga). Poin Xtra CIMB (spesifikasi dan harga varian Windows 10). Tokopedia. Intel ARK (N4020). | F6: Tahun rilis, status penjualan, charger, sidik jari, keyboard berlampu, webcam, versi HDMI, bahan bodi, jumlah slot M.2 yang kosong. Wi-Fi dan Bluetooth hanya ada di halaman Poin Xtra (varian Windows 10); bobot 1,4 kg dari halaman toko, bukan dari Axioo. | G6: Di situs Axioo, laptop dengan spesifikasi sama tertulis Hype 1 Intel dan tidak ada di daftar produk saat ini. Halaman Poin Xtra untuk Hype 10 memakai kalimat spesifikasi layar yang sama dengan situs Axioo, jadi keduanya kemungkinan besar produk yang sama (belum dikonfirmasi Axioo). RAM: 1 slot SODIMM, maksimal 8 GB. Penyimpanan: 2 slot M.2 2280 SATA. Kedua USB-C hanya untuk data. Ada versi Windows 10 dan Windows 11. Di Tokopedia, 5 dari 10 listing berharga Rp8-14,1 juta (tidak dipakai).
A7: =IF(Model!C8="","",Model!B8&" "&Model!C8) -> Lenovo ThinkPad T480 | B7: =IF(Model!D8="","",Model!D8) -> Bekas 1 | D7: Lenovo menulis rentang (bobot, baterai, layar) tanpa menyebut konfigurasi bekas. Manual servis (HMM) terlalu besar untuk dibuka. Banyak listing mencampur beberapa seri (T460, T470, T480). | E7: Lenovo PSREF T480 (spesifikasi resmi). Windows Central (ulasan). ITmedia (pengumuman CES 2018). Intel ARK (i5-8350U). Tokopedia (harga bekas). | F7: Kode varian, tipe SSD (NVMe atau SATA), jenis dan resolusi layar, layar sentuh, baterai, charger, sidik jari, keyboard berlampu, sistem operasi, lama garansi toko. | G7: Menurut Lenovo, penyimpanan utama memakai satu slot HDD 2,5 inci atau satu slot M.2 2280. RAM 2 slot, maksimal 32 GB. Windows Central: baterai luar bisa diganti saat laptop menyala. Status bekas_saja adalah dugaan (yang ditemukan hanya listing bekas). Harga i5-8350U 8/256: Rp3,15-4,16 juta (median Rp3,5 juta).
A8: =IF(Model!C9="","",Model!B9&" "&Model!C9) -> Dell Latitude 5400 | B8: =IF(Model!D9="","",Model!D9) -> Bekas 2 | D8: Panduan spesifikasi Dell ada dalam banyak salinan dengan tanggal berbeda. Halaman listing perorangan di Tokopedia tidak bisa dibuka (butuh JavaScript), jadi harga diambil dari halaman hasil pencarian. | E8: Dell (panduan spesifikasi, manual servis, panduan visual port). LaptopMedia (ulasan 6 Agustus 2019). Intel ARK (i5-8265U, i5-8365U). Tokopedia (harga bekas). | F8: Kode varian, tipe SSD (NVMe atau SATA), jenis dan resolusi layar, layar sentuh, baterai, charger, Wi-Fi, sidik jari, keyboard berlampu, webcam, sistem operasi, lama garansi toko, isi daya lewat USB-C. | G8: Dua slot RAM (maksimal 32 GB), satu slot M.2. Pada unit baterai 4-sel (68 Wh), ruang hard disk 2,5 inci tidak bisa dipakai (catatan manual servis Dell). Bodi serat karbon. Tahun 2019 dari tanggal ulasan LaptopMedia. Harga i5-8265U 8/256: Rp3,0-3,1 juta; i5-8365U 8/256: Rp3,5-4,2 juta.
A10: Ringkasan waktu
A11: Jumlah laptop yang sudah dicatat waktunya | B11: =COUNT(C4:C8) -> 0
A12: Rata-rata menit per laptop | B12: =IFERROR(AVERAGE(C4:C8),"")
A13: Target jumlah model (batas bawah) | B13: 40
A14: Target jumlah model (batas atas) | B14: 60
A15: Perkiraan total jam (batas bawah) | B15: =IFERROR(B12*B13/60,"")
A16: Perkiraan total jam (batas atas) | B16: =IFERROR(B12*B14/60,"")
A18: Tingkat 1-5 untuk CPU dan GPU di tab CPU dan GPU adalah usulan awal dari saya, bukan skor resmi. Tinjau alasannya sebelum dipakai untuk aturan penilaian.

Sheet Aturan
A1: Aturan penilaian: usulan awal (Draf 2)
A2: Ubah angka di kolom kuning untuk mencoba aturan lain; tab Perhitungan dan Hasil ikut berubah. Semua angka di sini adalah penilaian awal kita dan belum diuji ke pengguna.
A4: 1. Cara membaca hasil
A5: Status tiap kriteria | B5: Artinya
A6: Nyaman | B6: Nilai sudah mencapai batas nyaman.
A7: Cukup | B7: Nilai sudah mencapai batas minimal, tetapi belum mencapai batas nyaman.
A8: Kurang | B8: Nilai masih di bawah batas minimal.
A9: Belum ada data | B9: Nilainya masih kosong atau unknown di tab Varian, jadi belum bisa dinilai. Data yang kosong tidak dianggap bagus dan tidak dianggap jelek.
A10: Tidak dinilai | B10: Batas minimal dan batas nyaman sama-sama dikosongkan, jadi kriteria ini tidak dipakai untuk kebutuhan tersebut.
A12: Hasil akhir | B12: Syaratnya (dari atas ke bawah)
A13: Kurang cocok | B13: Ada satu kriteria atau lebih yang berstatus Kurang.
A14: Data belum lengkap | B14: Tidak ada yang Kurang, tetapi ada kriteria yang berstatus Belum ada data. Hasil ditahan sampai datanya lengkap.
A15: Bisa, dengan catatan | B15: Tidak ada yang Kurang dan data lengkap, tetapi ada kriteria yang baru Cukup. Alasannya ditulis di tab Hasil.
A16: Cocok | B16: Semua kriteria yang dinilai berstatus Nyaman.
A17: Tidak dinilai | B17: Semua batas untuk kebutuhan itu dikosongkan, jadi tidak ada yang bisa dinilai (dicek paling awal).
A19: 2. Kebutuhan yang dinilai (nama boleh diubah; tab lain ikut berubah)
A20: Kebutuhan | B20: Contoh pemakaian
A21: Kuliah dan kantor | B21: Mengetik tugas dan laporan, Word, Excel, dan PowerPoint, membuka banyak tab browser, rapat lewat Zoom atau Meet, menonton video kuliah.
A22: Desain grafis | B22: Photoshop, Illustrator, Figma, atau Canva; edit foto, desain poster, dan edit video ringan.
A23: Pemrograman | B23: Menulis kode di VS Code atau IDE lain, menjalankan server lokal, Docker atau mesin virtual, Android Studio, dan membuka banyak halaman dokumentasi.
A24: Game ringan | B24: Game yang tidak terlalu menuntut, seperti Minecraft, Valorant, atau Dota 2 pada pengaturan grafis rendah sampai sedang.
A25: Game berat | B25: Game 3D baru yang menuntut (sering disebut AAA) pada pengaturan sedang sampai tinggi.
A27: 3. Batas penilaian per kebutuhan
A28: Batas minimal: di bawah angka ini berstatus Kurang. Batas nyaman: dari angka ini berstatus Nyaman. Kosongkan kedua batas bila kriteria itu tidak dinilai untuk kebutuhan tersebut.
A29: Kebutuhan | B29: Kriteria | C29: Batas minimal | D29: Batas nyaman | E29: Satuan | F29: Alasan (bahasa awam) | G29: Dasar angka
A30: =$A$21 -> Kuliah dan kantor | B30: Prosesor (tingkat 1-5) | C30: 1 | D30: 2 | E30: tingkat | F30: Dokumen dan internet berjalan di prosesor dasar, tetapi terasa lambat bila banyak tab dan aplikasi dibuka bersamaan. Tingkat 2 sudah cukup lancar untuk kuliah dan kantor. | G30: Penilaian awal
A31: =$A$21 -> Kuliah dan kantor | B31: Kartu grafis (tingkat 1-5) | E31: tingkat | F31: Tidak dinilai: grafis bawaan apa pun cukup untuk dokumen, internet, dan video. | G31: -
A32: =$A$21 -> Kuliah dan kantor | B32: RAM | C32: 4 | D32: 8 | E32: GB | F32: 4 GB adalah syarat minimum Windows 11, tetapi cepat penuh bila banyak tab terbuka. 8 GB terasa lega untuk kuliah dan kantor. | G32: Batas minimal: syarat minimum Windows 11 (Microsoft). Batas nyaman: penilaian awal.
A33: =$A$21 -> Kuliah dan kantor | B33: Penyimpanan | C33: 128 | D33: 256 | E33: GB | F33: Windows 11 meminta minimal 64 GB. 128 GB cukup untuk Windows, Office, dan tugas, tetapi cepat penuh bila banyak video. 256 GB lebih lega. | G33: Dasar: syarat Windows 11 (64 GB, Microsoft). Angka 128 dan 256: penilaian awal.
A34: =$A$21 -> Kuliah dan kantor | B34: Jenis layar (peringkat) | E34: peringkat | F34: Tidak dinilai: jenis layar tidak menentukan cocok atau tidaknya untuk dokumen. Panel TN dan resolusi rendah tetap muncul sebagai peringatan. | G34: -
A35: =$A$21 -> Kuliah dan kantor | B35: Refresh rate layar | E35: Hz | F35: Tidak dinilai: refresh rate hanya penting untuk game. | G35: -
A36: =$A$22 -> Desain grafis | B36: Prosesor (tingkat 1-5) | C36: 2 | D36: 3 | E36: tingkat | F36: Aplikasi desain terasa lancar mulai tingkat 3. Tingkat 2 masih bisa untuk berkas kecil, tetapi lambat saat berkas besar atau banyak lapisan (layer). | G36: Penilaian awal; belum dicocokkan dengan syarat sistem aplikasinya
A37: =$A$22 -> Desain grafis | B37: Kartu grafis (tingkat 1-5) | C37: 1 | D37: 2 | E37: tingkat | F37: Grafis bawaan generasi baru (tingkat 2) membantu mempercepat tampilan dan filter. Grafis paling dasar (tingkat 1) tetap bisa dipakai, tetapi lebih lambat. | G37: Penilaian awal; belum dicocokkan dengan syarat sistem aplikasinya
A38: =$A$22 -> Desain grafis | B38: RAM | C38: 8 | D38: 16 | E38: GB | F38: Aplikasi desain memakai banyak RAM, apalagi untuk berkas besar. 8 GB cukup untuk belajar dan berkas kecil; 16 GB lebih nyaman. | G38: Penilaian awal; belum dicocokkan dengan syarat sistem aplikasinya
A39: =$A$22 -> Desain grafis | B39: Penyimpanan | C39: 256 | D39: 512 | E39: GB | F39: Berkas desain, foto, dan video cepat memenuhi penyimpanan. 512 GB lebih lega. | G39: Penilaian awal
A40: =$A$22 -> Desain grafis | B40: Jenis layar (peringkat) | C40: 3 | D40: 4 | E40: peringkat | F40: Jenis layar dipakai sebagai perkiraan kasar mutu warna, karena cakupan warna (sRGB atau DCI-P3) belum dicatat. TN dan VA umumnya kalah dalam ketepatan warna, IPS cukup, OLED umumnya mencakup warna lebih luas. Nanti diganti dengan data cakupan warna. | G40: Penilaian awal
A41: =$A$22 -> Desain grafis | B41: Refresh rate layar | E41: Hz | F41: Tidak dinilai: refresh rate tidak menentukan untuk desain. | G41: -
A42: =$A$23 -> Pemrograman | B42: Prosesor (tingkat 1-5) | C42: 2 | D42: 3 | E42: tingkat | F42: Kompilasi dan alat pengembang lebih cepat di tingkat 3. Tingkat 2 masih bisa untuk proyek kuliah, tetapi lebih lama saat proyek besar. | G42: Penilaian awal; belum dicocokkan dengan syarat sistem aplikasinya
A43: =$A$23 -> Pemrograman | B43: Kartu grafis (tingkat 1-5) | E43: tingkat | F43: Tidak dinilai: pemrograman umum tidak bergantung pada kartu grafis. Pekerjaan khusus seperti pembelajaran mesin (machine learning) yang butuh GPU belum dinilai. | G43: -
A44: =$A$23 -> Pemrograman | B44: RAM | C44: 8 | D44: 16 | E44: GB | F44: Editor kode, browser, dan server lokal masih muat di 8 GB. Docker, mesin virtual, atau Android Studio terasa lebih lega di 16 GB. | G44: Penilaian awal; belum dicocokkan dengan syarat sistem aplikasinya
...

Sheet Perhitungan
A1: Perhitungan: satu baris untuk satu pasangan varian dan kebutuhan
A2: Semuanya rumus dari tab Varian, CPU, GPU, dan Aturan, jadi tidak ada yang diketik di sini. Dipakai untuk menelusuri bagaimana tiap hasil didapat. Tiap varian memakai lima baris berurutan (satu per kebutuhan).
A3: Pasangan yang dihitung | C3: Nilai dari tab Varian | I3: Info upgrade | K3: Status tiap kriteria | Q3: Hasil | R3: Kalimat alasan per kriteria | X3: Alasan | AA3: Peringatan umum (baris pertama tiap varian)
A4: Varian id_varian | B4: Kebutuhan kebutuhan | C4: Prosesor · tingkat cpu_tier | D4: Grafis · tingkat gpu_tier | E4: RAM (GB) ram_gb | F4: Penyimpanan (GB) st_gb | G4: Layar · peringkat layar_rank | H4: Refresh (Hz) refresh_hz | I4: Catatan upgrade RAM catatan_ram | J4: Catatan upgrade penyimpanan catatan_st | K4: Status · prosesor status_cpu | L4: Status · grafis status_gpu | M4: Status · RAM status_ram | N4: Status · penyimpanan status_st | O4: Status · layar status_layar | P4: Status · refresh status_refresh | Q4: Hasil hasil | R4: Kalimat · prosesor kal_cpu | S4: Kalimat · grafis kal_gpu | T4: Kalimat · RAM kal_ram | U4: Kalimat · penyimpanan kal_st | V4: Kalimat · layar kal_layar | W4: Kalimat · refresh kal_refresh | X4: Daftar masalah (mentah) masalah | Y4: Daftar yang nyaman (mentah) nyaman | Z4: Alasan alasan | AA4: Peringatan (mentah) peringatan_mentah | AB4: Peringatan peringatan | AC4: Jumlah peringatan peringatan_jml
